<?xml version="1.0" encoding="utf-8"?>
<!-- This URDF was automatically created by SolidWorks to URDF Exporter! Originally created by Stephen Brawner (brawner@gmail.com) 
     Commit Version: 1.6.0-4-g7f85cfe  Build Version: 1.6.7995.38578
     For more information, please see http://wiki.ros.org/sw_urdf_exporter -->
<robot
  name="solid2ROS">
  <link
    name="base_link">
    <inertial>
      <origin
        xyz="6.9389E-17 -3.8734E-16 0.073876"
        rpy="0 0 0" />
      <mass
        value="17.147" />
      <inertia
        ixx="0.192"
        ixy="-4.9423E-10"
        ixz="3.2838E-17"
        iyy="0.192"
        iyz="-5.5541E-16"
        izz="0.29544" />
    </inertial>
    <visual>
      <origin
        xyz="0 0 0"
        rpy="0 0 0" />
      <geometry>
        <mesh
          filename="package://solid2ROS/meshes/base_link.STL" />
      </geometry>
      <material
        name="">
        <color
          rgba="0.79216 0.81961 0.93333 1" />
      </material>
    </visual>
    <collision>
      <origin
        xyz="0 0 0"
        rpy="0 0 0" />
      <geometry>
        <mesh
          filename="package://solid2ROS/meshes/base_link.STL" />
      </geometry>
    </collision>
  </link>
  <link
    name="Link_1">
    <inertial>
      <origin
        xyz="-2.5676E-14 7.8987E-11 0.11047"
        rpy="0 0 0" />
      <mass
        value="3.0905" />
      <inertia
        ixx="0.026302"
        ixy="1.4177E-12"
        ixz="-2.5271E-15"
        iyy="0.025388"
        iyz="7.4536E-12"
        izz="0.019632" />
    </inertial>
    <visual>
      <origin
        xyz="0 0 0"
        rpy="-1.5707 0 0" />
      <geometry>
        <mesh
          filename="package://solid2ROS/meshes/Link_1.STL" />
      </geometry>
      <material
        name="">
        <color
          rgba="1 1 1 1" />
      </material>
    </visual>
    <collision>
      <origin
        xyz="0 0 0"
        rpy="-1.5707 0 0" />
      <geometry>
        <mesh
          filename="package://solid2ROS/meshes/Link_1.STL" />
      </geometry>
    </collision>
  </link>
  <joint
    name="Joint_1"
    type="revolute">
    <origin
      xyz="0 0 0.2"
      rpy="1.5708 0 1.5708" />
    <parent
      link="base_link" />
    <child
      link="Link_1" />
    <axis
      xyz="0 1 0" />
    <limit
      lower="0"
      upper="3.142"
      effort="300"
      velocity="3" />
  </joint>
  <link
    name="Link_2">
    <inertial>
      <origin
        xyz="-3.4694E-18 0.16752 -5.6279E-19"
        rpy="0 0 0" />
      <mass
        value="5.5867" />
      <inertia
        ixx="0.12632"
        ixy="3.5867E-18"
        ixz="5.0249E-19"
        iyy="0.011401"
        iyz="6.7098E-18"
        izz="0.12911" />
    </inertial>
    <visual>
      <origin
        xyz="0 0 0"
        rpy="0 0 0" />
      <geometry>
        <mesh
          filename="package://solid2ROS/meshes/Link_2.STL" />
      </geometry>
      <material
        name="">
        <color
          rgba="0.79216 0.81961 0.93333 1" />
      </material>
    </visual>
    <collision>
      <origin
        xyz="0 0 0"
        rpy="0 0 0" />
      <geometry>
        <mesh
          filename="package://solid2ROS/meshes/Link_2.STL" />
      </geometry>
    </collision>
  </link>
  <joint
    name="Joint_2"
    type="revolute">
    <origin
      xyz="0 0.205 0"
      rpy="0 0 0" />
    <parent
      link="Link_1" />
    <child
      link="Link_2" />
    <axis
      xyz="0 0 1" />
    <limit
      lower="-1.57"
      upper="1.57"
      effort="200"
      velocity="3" />
  </joint>
  <link
    name="Link_3">
    <inertial>
      <origin
        xyz="0.178930262066801 -2.22044604925031E-16 -1.02928275371533E-16"
        rpy="0 0 3.141592" />
      <mass
        value="2.82619520391382" />
      <inertia
        ixx="0.00740408211087425"
        ixy="-1.54945966744134E-18"
        ixz="3.6909075064265E-17"
        iyy="0.0285515471738977"
        iyz="3.47356812267738E-10"
        izz="0.0251280922457047" />
    </inertial>
    <visual>
      <origin
        xyz="0 0 0"
        rpy="0 0 3.141592" />
      <geometry>
        <mesh
          filename="package://solid2ROS/meshes/Link_3.STL" />
      </geometry>
      <material
        name="">
        <color
          rgba="0.792156862745098 0.819607843137255 0.933333333333333 1" />
      </material>
    </visual>
    <collision>
      <origin
        xyz="0 0 0"
        rpy="0 0 3.141592" />
      <geometry>
        <mesh
          filename="package://solid2ROS/meshes/Link_3.STL" />
      </geometry>
    </collision>
  </link>
  <joint
    name="Joint_3"
    type="revolute">
    <origin
      xyz="0 0.4 0"
      rpy="0 0 0" />
    <parent
      link="Link_2" />
    <child
      link="Link_3" />
    <axis
      xyz="0 0 1" />
    <limit
      lower="0"
      upper="3.142"
      effort="200"
      velocity="3" />
  </joint>
  <link
    name="Link_4">
    <inertial>
      <origin
        xyz="-0.0516721734345446 -5.55111512312578E-17 -2.79397508924487E-16"
        rpy="0 0 0" />
      <mass
        value="1.80974470730009" />
      <inertia
        ixx="0.00231117416637535"
        ixy="-5.68627638675112E-18"
        ixz="-3.89981354353928E-17"
        iyy="0.00961023623935307"
        iyz="-7.5852462171116E-19"
        izz="0.00939078362141456" />
    </inertial>
    <visual>
      <origin
        xyz="0 0 0"
        rpy="0 0 0" />
      <geometry>
        <mesh
          filename="package://solid2ROS/meshes/Link_4.STL" />
      </geometry>
      <material
        name="">
        <color
          rgba="0.792156862745098 0.819607843137255 0.933333333333333 1" />
      </material>
    </visual>
    <collision>
      <origin
        xyz="0 0 0"
        rpy="0 0 0" />
      <geometry>
        <mesh
          filename="package://solid2ROS/meshes/Link_4.STL" />
      </geometry>
    </collision>
  </link>
  <joint
    name="Joint_4"
    type="revolute">
    <origin
      xyz="-0.35 0 0"
      rpy="0 0 1.5708" />
    <parent
      link="Link_3" />
    <child
      link="Link_4" />
    <axis
      xyz="0 0 1" />
    <limit
      lower="0"
      upper="-3.142"
      effort="200"
      velocity="3" />
  </joint>
  <link
    name="Link_5">
    <inertial>
      <origin
        xyz="0 4.10936282126392E-17 0.00654388120672444"
        rpy="0 -1.5707 0" />
      <mass
        value="0.190534239699016" />
      <inertia
        ixx="0.000228167325721982"
        ixy="1.96636695190795E-11"
        ixz="-4.20929595481781E-20"
        iyy="0.000118429273152252"
        iyz="-2.39301170186938E-20"
        izz="0.00030196507003955" />
    </inertial>
    <visual>
      <origin
        xyz="0 0 0"
        rpy="0 -1.5707 0" />
      <geometry>
        <mesh
          filename="package://solid2ROS/meshes/Link_5.STL" />
      </geometry>
      <material
        name="">
        <color
          rgba="0.792156862745098 0.819607843137255 0.933333333333333 1" />
      </material>
    </visual>
    <collision>
      <origin
        xyz="0 0 0"
        rpy="0 -1.5707 0" />
      <geometry>
        <mesh
          filename="package://solid2ROS/meshes/Link_5.STL" />
      </geometry>
    </collision>
  </link>
  <joint
    name="Joint_5"
    type="revolute">
    <origin
      xyz="-0.188 0 0"
      rpy="0 0 0" />
    <parent
      link="Link_4" />
    <child
      link="Link_5" />
    <axis
      xyz="1 0 0" />
    <limit
      lower="0"
      upper="3.142"
      effort="200"
      velocity="3" />
  </joint>
  <link
    name="Link_6">
    <inertial>
      <origin
        xyz="0 4.10936282126392E-17 0.00654388120672444"
        rpy="0 0 0" />
      <mass
        value="0.11653" />
      <inertia
        ixx="7.1189E-05"
        ixy="5.9471E-20"
        ixz="2.0987E-20"
        iyy="8.4875E-05"
        iyz="-1.0258E-05"
        izz="3.9246E-05" />
    </inertial>
    <visual>
      <origin
        xyz="0 0 0"
        rpy="0 -1.5707 0" />
      <geometry>
        <mesh
          filename="package://solid2ROS/meshes/Link_6.STL" />
      </geometry>
      <material
        name="">
        <color
          rgba="0.79216 0.81961 0.93333 1" />
      </material>
    </visual>
    <collision>
      <origin
        xyz="0 0 0"
        rpy="0 -1.5707 0" />
      <geometry>
        <mesh
          filename="package://solid2ROS/meshes/Link_6.STL" />
      </geometry>
    </collision>
  </link>
  <joint
    name="Joint_6"
    type="prismatic">
    <origin
      xyz="0 0 0"
      rpy="0 0 0" />
    <parent
      link="Link_5" />
    <child
      link="Link_6" />
    <axis
      xyz="0 1 0" />
    <limit
      lower="0"
      upper="-0.03"
      effort="100"
      velocity="3" />
  </joint>
  <link
    name="Link_7">
    <inertial>
      <origin
        xyz="0 0.016013 0.050369"
        rpy="0 0 0" />
      <mass
        value="0.11653" />
      <inertia
        ixx="7.1189E-05"
        ixy="3.7951E-20"
        ixz="-6.8974E-20"
        iyy="8.4875E-05"
        iyz="1.0258E-05"
        izz="3.9246E-05" />
    </inertial>
    <visual>
      <origin
        xyz="0 0 0"
        rpy="0 -1.5707 0" />
      <geometry>
        <mesh
          filename="package://solid2ROS/meshes/Link_7.STL" />
      </geometry>
      <material
        name="">
        <color
          rgba="0.79216 0.81961 0.93333 1" />
      </material>
    </visual>
    <collision>
      <origin
        xyz="0 0 0"
        rpy="0 -1.5707 0" />
      <geometry>
        <mesh
          filename="package://solid2ROS/meshes/Link_7.STL" />
      </geometry>
    </collision>
  </link>
  <joint
    name="Joint_7"
    type="prismatic">
    <origin
      xyz="0 0 0"
      rpy="0 0 0" />
    <parent
      link="Link_5" />
    <child
      link="Link_7" />
    <axis
      xyz="0 1 0" />
    <limit
      lower="0"
      upper="0.03"
      effort="100"
      velocity="3" />
  </joint>
</robot>